F
======================================================================
FAIL: test_run (test_issue_742.ThrowsWhenSubBoxLengthIsNotGood)
----------------------------------------------------------------------
Traceback (most recent call last):
  File "/home/workspace/tests/system_tests.py", line 632, in test_run
    self.compare_stderr(i, command, processed_stderr, stderr)
  File "/home/workspace/tests/system_tests.py", line 755, in compare_stderr
    msg="Standard error does not match"
  File "/home/workspace/tests/system_tests.py", line 726, in _compare_output
    expected, got, msg=msg
AssertionError: 'Uncaught exception: std::bad_alloc\n' != 'Exiv2 exception in print action for file [64 chars]ta\n'
- Uncaught exception: std::bad_alloc
+ Exiv2 exception in print action for file /home/workspace/test/data/issue_742_poc:
+ corrupted image metadata
 : Standard error does not match

----------------------------------------------------------------------
Ran 1 test in 0.007s

FAILED (failures=1)
